<?xml version="1.0"?>
<sdf version="1.5">
	<model name="virat">
		<static>false</static>
        <link name="bot2">
            <pose>0 0 0.5 0 0 0</pose>
            <collision name="collision">
                <geometry>
                    <mesh>
                        <uri>model://bot2/meshes/bot2.dae</uri>
                        <scale>1 1 1</scale>
                    </mesh>
                </geometry>
                <surface>
                    <friction>
                        <ode>
                            <mu>100</mu>
                            <mu2>50</mu2>
                        </ode>
                    </friction>
                </surface>
            </collision>
            <visual name="visual">
                <geometry>
                    <mesh>
                        <uri>model://bot2/meshes/bot2.dae</uri>
                        <scale>1 1 1</scale>
                    </mesh>
                </geometry>
                <material>
                    <script>
                        <uri>file://media/materials/scripts/gazebo.material</uri>
                    </script>
                </material>
            </visual>
        </link>
        <link name="castor">
            <pose>0.427 0 0.5 0 0 0</pose>
            <collision name="collision">
                <geometry>
                    <mesh>
                        <uri>model://castors1/meshes/castors1.dae</uri>
                        <scale>1 1 1</scale>
                    </mesh>
                </geometry>
                <surface>
                    <friction>
                        <ode>
                            <mu>100</mu>
                            <mu2>50</mu2>
                        </ode>
                    </friction>
                </surface>
            </collision>
            <visual name="visual">
                <geometry>
                    <mesh>
                        <uri>model://castors1/meshes/castors1.dae</uri>
                        <scale>1 1 1</scale>
                    </mesh>
                </geometry>
                <material>
                    <script>
                        <uri>file://media/materials/scripts/gazebo.material</uri>
                    </script>
                </material>
            </visual>
        </link>
        <link name="tyre_left">
            <pose>0 0.332 0.5 0 0 0</pose>
            <collision name="collision">
                <geometry>
                    <mesh>
                        <uri>model://tyre1/meshes/tyre1.dae</uri>
                        <scale>1 1 1</scale>
                    </mesh>
                </geometry>
                <surface>
                    <friction>
                        <ode>
                            <mu>100</mu>
                            <mu2>50</mu2>
                        </ode>
                    </friction>
                </surface>
            </collision>
            <visual name="visual">
                <geometry>
                    <mesh>
                        <uri>model://tyre1/meshes/tyre1.dae</uri>
                        <scale>1 1 1</scale>
                    </mesh>
                </geometry>
                <material>
                    <script>
                        <uri>file://media/materials/scripts/gazebo.material</uri>
                    </script>
                </material>
            </visual>
        </link>
        <link name="tyre_right">
            <pose>0 -0.332 0.5 0 0 0</pose>
            <collision name="collision">
                <geometry>
                    <mesh>
                        <uri>model://tyre1/meshes/tyre1.dae</uri>
                        <scale>1 1 1</scale>
                    </mesh>
                </geometry>
                <surface>
                    <friction>
                        <ode>
                            <mu>100</mu>
                            <mu2>50</mu2>
                        </ode>
                    </friction>
                </surface>
            </collision>
            <visual name="visual">
                <geometry>
                    <mesh>
                        <uri>model://tyre1/meshes/tyre1.dae</uri>
                        <scale>1 1 1</scale>
                    </mesh>
                </geometry>
                <material>
                    <script>
                        <uri>file://media/materials/scripts/gazebo.material</uri>
                    </script>
                </material>
            </visual>
        </link>
        <joint type="revolute" name="left_wheel_hinge">
            <pose>0 0 0 0 0 0</pose>
            <child>tyre_left</child>
            <parent>bot2</parent>
            <axis>
                <xyz>0 1 0</xyz>
            </axis>
        </joint>
        <joint type="revolute" name="right_wheel_hinge">
            <pose>0 0 0 0 0 0</pose>
            <child>tyre_right</child>
            <parent>bot2</parent>
            <axis>
                <xyz>0 1 0</xyz>
            </axis>
        </joint>
        <joint type="revolute" name="castor_hinge">
            <pose>0 0 0 0 0 0</pose>
            <child>castor</child>
            <parent>bot2</parent>
            <axis>
                <xyz>0 0 1</xyz>
            </axis>
        </joint>
	</model>
</sdf>